Workbook

Sheet 2027 전학년
A1: 2027학년도 당해년도 전 학년(1, 2, 3학년) 교육과정 편성표
A2: 창원여자고등학교(공립)
A3: 구분 | B3: 교과(군) | C3: 과목 유형 | D3: 과목 | E3: 기본 학점 | F3: 운영 학점 | G3: 1학년 | I3: 2학년 | K3: 3학년 | M3: 개설 여부 | O3: 성적처리 유형
G4: 1학기 | H4: 2학기 | I4: 1학기 | J4: 2학기 | K4: 1학기 | L4: 2학기 | M4: 1학기 | N4: 2학기
A5: 학 교 지 정 과 목 | B5: 국어 | C5: 공통 | D5: 공통국어1 | E5: 4 | F5: =IF(SUM(G5:L5)<>0,SUM(G5:L5),F4) -> 3 | G5: 3 | M5: O | N5: X | O5: 성취도 5단계+석차등급O
C6: 공통 | D6: 공통국어2 | E6: 4 | F6: =IF(SUM(G6:L6)<>0,SUM(G6:L6),F5) -> 3 | H6: 3 | M6: O | N6: X | O6: 성취도 5단계+석차등급O
C7: 일반 | D7: 화법과 언어 | E7: 4 | F7: =SUM(G7:L7) -> 4 | I7: 4 | M7: O | N7: X | O7: 성취도 5단계+석차등급O
C8: 일반 | D8: 문학 | E8: 4 | F8: =SUM(G8:L8) -> 4 | J8: 4 | M8: O | N8: X | O8: 성취도 5단계+석차등급O
C9: 일반 | D9: 독서와 작문 | E9: 4 | F9: 4 | K9: 4 | O9: 성취도 5단계+석차등급O
C10: 진로 | D10: 주제 탐구 독서 | E10: 4 | F10: 4 | L10: 4 | O10: 성취도 5단계+석차등급O
B11: 수학 | C11: 공통 | D11: 공통수학1 | E11: 4 | F11: =IF(SUM(G11:L11)<>0,SUM(G11:L11),#REF!) -> 3 | G11: 3 | M11: O | N11: X | O11: 성취도 5단계+석차등급O
C12: 공통 | D12: 공통수학2 | E12: 4 | F12: =IF(SUM(G12:L12)<>0,SUM(G12:L12),F11) -> 3 | H12: 3 | M12: O | N12: X | O12: 성취도 5단계+석차등급O
C13: 일반 | D13: 대수 | E13: 4 | F13: =SUM(G13:L13) -> 4 | I13: 4 | M13: O | N13: X | O13: 성취도 5단계+석차등급O
C14: 일반 | D14: 미적분Ⅰ | E14: 4 | F14: =SUM(G14:L14) -> 4 | J14: 4 | M14: O | N14: X | O14: 성취도 5단계+석차등급O
C15: 일반 | D15: 확률과 통계 | E15: 4 | F15: 4 | K15: 4 | O15: 성취도 5단계+석차등급O
C16: 융합 | D16: 수학과 문화 | E16: 4 | F16: 4 | L16: 4 | O16: 성취도 5단계+석차등급O
B17: 영어 | C17: 공통 | D17: 공통영어1 | E17: 4 | F17: =IF(SUM(G17:L17)<>0,SUM(G17:L17),#REF!) -> 3 | G17: 3 | M17: O | N17: X | O17: 성취도 5단계+석차등급O
C18: 공통 | D18: 공통영어2 | E18: 4 | F18: =IF(SUM(G18:L18)<>0,SUM(G18:L18),F17) -> 3 | H18: 3 | M18: O | N18: X | O18: 성취도 5단계+석차등급O
C19: 일반 | D19: 영어Ⅰ | E19: 4 | F19: =SUM(G19:L19) -> 4 | I19: 4 | M19: O | N19: X | O19: 성취도 5단계+석차등급O
C20: 일반 | D20: 영어Ⅱ | E20: 4 | F20: =SUM(G20:L20) -> 4 | J20: 4 | M20: O | N20: X | O20: 성취도 5단계+석차등급O
C21: 일반 | D21: 영어 독해와 작문 | E21: 4 | F21: 4 | K21: 4 | O21: 성취도 5단계+석차등급O
C22: 진로 | D22: 심화 영어 독해와 작문 | E22: 4 | F22: 4 | L22: 4 | O22: 성취도 5단계+석차등급O
B23: 사회 | C23: 공통 | D23: 한국사1 | E23: 3 | F23: =IF(SUM(G23:L23)<>0,SUM(G23:L23),#REF!) -> 3 | G23: 3 | M23: O | N23: X | O23: 성취도 5단계+석차등급O
C24: 공통 | D24: 한국사2 | E24: 3 | F24: =IF(SUM(G24:L24)<>0,SUM(G24:L24),F23) -> 3 | H24: 3 | M24: O | N24: X | O24: 성취도 5단계+석차등급O
C25: 공통 | D25: 통합사회1 | E25: 4 | F25: =IF(SUM(G25:L25)<>0,SUM(G25:L25),F24) -> 4 | G25: 4 | M25: O | N25: X | O25: 성취도 5단계+석차등급O
C26: 공통 | D26: 통합사회2 | E26: 4 | F26: =IF(SUM(G26:L26)<>0,SUM(G26:L26),F25) -> 4 | H26: 4 | M26: O | N26: X | O26: 성취도 5단계+석차등급O
B27: 과학 | C27: 공통 | D27: 통합과학1 | E27: 4 | F27: =IF(SUM(G27:L27)<>0,SUM(G27:L27),F26) -> 4 | G27: 4 | M27: O | N27: X | O27: 성취도 5단계+석차등급O
C28: 공통 | D28: 통합과학2 | E28: 4 | F28: =IF(SUM(G28:L28)<>0,SUM(G28:L28),F27) -> 4 | H28: 4 | M28: O | N28: X | O28: 성취도 5단계+석차등급O
C29: 공통 | D29: 과학탐구실험1 | E29: 1 | F29: =IF(SUM(G29:L29)<>0,SUM(G29:L29),F28) -> 1 | G29: 1 | M29: O | N29: X | O29: 성취도 3단계
C30: 공통 | D30: 과학탐구실험2 | E30: 1 | F30: =IF(SUM(G30:L30)<>0,SUM(G30:L30),F29) -> 1 | H30: 1 | M30: O | N30: X | O30: 성취도 3단계
B31: 체육 | C31: 일반 | D31: 체육1 | E31: 3 | F31: =IF(SUM(G31:L31)<>0,SUM(G31:L31),F30) -> 2 | G31: 2 | M31: O | N31: X | O31: 성취도 3단계
C32: 일반 | D32: 체육2 | E32: 3 | F32: =IF(SUM(G32:L32)<>0,SUM(G32:L32),F31) -> 2 | H32: 2 | M32: O | N32: X | O32: 성취도 3단계
C33: 융합 | D33: 스포츠 생활1 | E33: 3 | F33: =SUM(G33:L33) -> 2 | I33: 2 | M33: O | N33: X | O33: 성취도 3단계
C34: 융합 | D34: 스포츠 생활2 | E34: 3 | F34: =SUM(G34:L34) -> 2 | J34: 2 | M34: O | N34: X | O34: 성취도 3단계
C35: 진로 | D35: 스포츠 문화 | E35: 2 | F35: 1 | K35: 1 | O35: 성취도 3단계
C36: 진로 | D36: 스포츠 과학 | E36: 2 | F36: 1 | L36: 1 | M36: O | N36: X | O36: 성취도 3단계
B37: 예술 | C37: 일반 | D37: 음악↔미술 | E37: 3 | F37: 3 | G37: 3 | H37: 3 | M37: O | N37: X | O37: 성취도 3단계
C38: 일반 | E38: 3 | F38: 3 | M38: O | N38: X | O38: 성취도 3단계
C39: 진로 | D39: 음악 연주와 창작↔미술 창작 | E39: 3 | F39: 2 | K39: 2 | L39: 2 | O39: 성취도 3단계
C40: 진로 | E40: 3 | F40: 2 | M40: O | N40: X | O40: 성취도 3단계
...

Sheet 2027 입학생 3개년(1학년)
A1: 2027학년도 입학생 3개년 교육과정 편성표(1학년)
A2: 창원여자고등학교(공립)
A3: 구분 | B3: 교과(군) | C3: 과목 유형 | D3: 과목 | E3: 기본 학점 | F3: 운영 학점 | G3: 1학년 | I3: 2학년 | K3: 3학년 | M3: 편성학점 합 | O3: 성적처리 유형
G4: 1학기 | H4: 2학기 | I4: 1학기 | J4: 2학기 | K4: 1학기 | L4: 2학기 | M4: 교과(군) | N4: 선택군
A5: 학 교 지 정 과 목 | B5: 국어 | C5: =VLOOKUP(D5,[1]숨김!$B$3:$E$300,2,0) -> 공통 | D5: 공통국어1 | E5: =VLOOKUP(D5,[1]숨김!$B$3:$E$300,3,0) -> 4 | F5: =SUM(G5:L5) -> 3 | G5: 3 | M5: =SUM(G5:L10) -> 22 | N5: =SUM(M5,M11,M17) -> 66 | O5: =VLOOKUP(D5,[1]숨김!$B$3:$E$300,4,0) -> 성취도 5단계+석차등급O
C6: =VLOOKUP(D6,[1]숨김!$B$3:$E$300,2,0) -> 공통 | D6: 공통국어2 | E6: =VLOOKUP(D6,[1]숨김!$B$3:$E$300,3,0) -> 4 | F6: =SUM(G6:L6) -> 3 | H6: 3 | O6: =VLOOKUP(D6,[1]숨김!$B$3:$E$300,4,0) -> 성취도 5단계+석차등급O
C7: =VLOOKUP(D7,[1]숨김!$B$3:$E$300,2,0) -> 일반 | D7: 화법과 언어 | E7: =VLOOKUP(D7,[1]숨김!$B$3:$E$300,3,0) -> 4 | F7: =SUM(G7:L7) -> 4 | I7: 4 | O7: =VLOOKUP(D7,[1]숨김!$B$3:$E$300,4,0) -> 성취도 5단계+석차등급O
C8: =VLOOKUP(D8,[1]숨김!$B$3:$E$300,2,0) -> 일반 | D8: 문학 | E8: =VLOOKUP(D8,[1]숨김!$B$3:$E$300,3,0) -> 4 | F8: =SUM(G8:L8) -> 4 | J8: 4 | O8: =VLOOKUP(D8,[1]숨김!$B$3:$E$300,4,0) -> 성취도 5단계+석차등급O
C9: =VLOOKUP(D9,[1]숨김!$B$3:$E$300,2,0) -> 일반 | D9: 독서와 작문 | E9: =VLOOKUP(D9,[1]숨김!$B$3:$E$300,3,0) -> 4 | F9: =SUM(G9:L9) -> 4 | K9: 4 | O9: =VLOOKUP(D9,[1]숨김!$B$3:$E$300,4,0) -> 성취도 5단계+석차등급O
C10: =VLOOKUP(D10,[1]숨김!$B$3:$E$300,2,0) -> 진로 | D10: 주제 탐구 독서 | E10: =VLOOKUP(D10,[1]숨김!$B$3:$E$300,3,0) -> 4 | F10: =SUM(G10:L10) -> 4 | L10: 4 | O10: =VLOOKUP(D10,[1]숨김!$B$3:$E$300,4,0) -> 성취도 5단계+석차등급O
B11: 수학 | C11: =VLOOKUP(D11,[1]숨김!$B$3:$E$300,2,0) -> 공통 | D11: 공통수학1 | E11: =VLOOKUP(D11,[1]숨김!$B$3:$E$300,3,0) -> 4 | F11: =SUM(G11:L11) -> 3 | G11: 3 | M11: =SUM(G11:L16) -> 22 | O11: =VLOOKUP(D11,[1]숨김!$B$3:$E$300,4,0) -> 성취도 5단계+석차등급O
C12: =VLOOKUP(D12,[1]숨김!$B$3:$E$300,2,0) -> 공통 | D12: 공통수학2 | E12: =VLOOKUP(D12,[1]숨김!$B$3:$E$300,3,0) -> 4 | F12: =SUM(G12:L12) -> 3 | H12: 3 | O12: =VLOOKUP(D12,[1]숨김!$B$3:$E$300,4,0) -> 성취도 5단계+석차등급O
C13: =VLOOKUP(D13,[1]숨김!$B$3:$E$300,2,0) -> 일반 | D13: 대수 | E13: =VLOOKUP(D13,[1]숨김!$B$3:$E$300,3,0) -> 4 | F13: =SUM(G13:L13) -> 4 | I13: 4 | O13: =VLOOKUP(D13,[1]숨김!$B$3:$E$300,4,0) -> 성취도 5단계+석차등급O
C14: =VLOOKUP(D14,[1]숨김!$B$3:$E$300,2,0) -> 일반 | D14: 미적분Ⅰ | E14: =VLOOKUP(D14,[1]숨김!$B$3:$E$300,3,0) -> 4 | F14: =SUM(G14:L14) -> 4 | J14: 4 | O14: =VLOOKUP(D14,[1]숨김!$B$3:$E$300,4,0) -> 성취도 5단계+석차등급O
C15: =VLOOKUP(D15,[1]숨김!$B$3:$E$300,2,0) -> 일반 | D15: 확률과 통계 | E15: =VLOOKUP(D15,[1]숨김!$B$3:$E$300,3,0) -> 4 | F15: =SUM(G15:L15) -> 4 | K15: 4 | O15: =VLOOKUP(D15,[1]숨김!$B$3:$E$300,4,0) -> 성취도 5단계+석차등급O
C16: =VLOOKUP(D16,[1]숨김!$B$3:$E$300,2,0) -> 융합 | D16: 수학과 문화 | E16: =VLOOKUP(D16,[1]숨김!$B$3:$E$300,3,0) -> 4 | F16: =SUM(G16:L16) -> 4 | L16: 4 | O16: =VLOOKUP(D16,[1]숨김!$B$3:$E$300,4,0) -> 성취도 5단계+석차등급O
B17: 영어 | C17: =VLOOKUP(D17,[1]숨김!$B$3:$E$300,2,0) -> 공통 | D17: 공통영어1 | E17: =VLOOKUP(D17,[1]숨김!$B$3:$E$300,3,0) -> 4 | F17: =SUM(G17:L17) -> 3 | G17: 3 | M17: =SUM(G17:L22) -> 22 | O17: =VLOOKUP(D17,[1]숨김!$B$3:$E$300,4,0) -> 성취도 5단계+석차등급O
C18: =VLOOKUP(D18,[1]숨김!$B$3:$E$300,2,0) -> 공통 | D18: 공통영어2 | E18: =VLOOKUP(D18,[1]숨김!$B$3:$E$300,3,0) -> 4 | F18: =SUM(G18:L18) -> 3 | H18: 3 | O18: =VLOOKUP(D18,[1]숨김!$B$3:$E$300,4,0) -> 성취도 5단계+석차등급O
C19: =VLOOKUP(D19,[1]숨김!$B$3:$E$300,2,0) -> 일반 | D19: 영어Ⅰ | E19: =VLOOKUP(D19,[1]숨김!$B$3:$E$300,3,0) -> 4 | F19: =SUM(G19:L19) -> 4 | I19: 4 | O19: =VLOOKUP(D19,[1]숨김!$B$3:$E$300,4,0) -> 성취도 5단계+석차등급O
C20: =VLOOKUP(D20,[1]숨김!$B$3:$E$300,2,0) -> 일반 | D20: 영어Ⅱ | E20: =VLOOKUP(D20,[1]숨김!$B$3:$E$300,3,0) -> 4 | F20: =SUM(G20:L20) -> 4 | J20: 4 | O20: =VLOOKUP(D20,[1]숨김!$B$3:$E$300,4,0) -> 성취도 5단계+석차등급O
C21: =VLOOKUP(D21,[1]숨김!$B$3:$E$300,2,0) -> 일반 | D21: 영어 독해와 작문 | E21: =VLOOKUP(D21,[1]숨김!$B$3:$E$300,3,0) -> 4 | F21: =SUM(G21:L21) -> 4 | K21: 4 | O21: =VLOOKUP(D21,[1]숨김!$B$3:$E$300,4,0) -> 성취도 5단계+석차등급O
C22: =VLOOKUP(D22,[1]숨김!$B$3:$E$300,2,0) -> 진로 | D22: 심화 영어 독해와 작문 | E22: =VLOOKUP(D22,[1]숨김!$B$3:$E$300,3,0) -> 4 | F22: =SUM(G22:L22) -> 4 | L22: 4 | O22: =VLOOKUP(D22,[1]숨김!$B$3:$E$300,4,0) -> 성취도 5단계+석차등급O
B23: 사회 | C23: =VLOOKUP(D23,[1]숨김!$B$3:$E$300,2,0) -> 공통 | D23: 한국사1 | E23: =VLOOKUP(D23,[1]숨김!$B$3:$E$300,3,0) -> 3 | F23: =SUM(G23:L23) -> 3 | G23: 3 | M23: =SUM(G23:L24) -> 6 | O23: =VLOOKUP(D23,[1]숨김!$B$3:$E$300,4,0) -> 성취도 5단계+석차등급O
C24: =VLOOKUP(D24,[1]숨김!$B$3:$E$300,2,0) -> 공통 | D24: 한국사2 | E24: =VLOOKUP(D24,[1]숨김!$B$3:$E$300,3,0) -> 3 | F24: =SUM(G24:L24) -> 3 | H24: 3 | O24: =VLOOKUP(D24,[1]숨김!$B$3:$E$300,4,0) -> 성취도 5단계+석차등급O
C25: =VLOOKUP(D25,[1]숨김!$B$3:$E$300,2,0) -> 공통 | D25: 통합사회1 | E25: =VLOOKUP(D25,[1]숨김!$B$3:$E$300,3,0) -> 4 | F25: =SUM(G25:L25) -> 4 | G25: 4 | M25: =SUM(G25:L26) -> 8 | O25: =VLOOKUP(D25,[1]숨김!$B$3:$E$300,4,0) -> 성취도 5단계+석차등급O
C26: =VLOOKUP(D26,[1]숨김!$B$3:$E$300,2,0) -> 공통 | D26: 통합사회2 | E26: =VLOOKUP(D26,[1]숨김!$B$3:$E$300,3,0) -> 4 | F26: =SUM(G26:L26) -> 4 | H26: 4 | O26: =VLOOKUP(D26,[1]숨김!$B$3:$E$300,4,0) -> 성취도 5단계+석차등급O
B27: 과학 | C27: =VLOOKUP(D27,[1]숨김!$B$3:$E$300,2,0) -> 공통 | D27: 통합과학1 | E27: =VLOOKUP(D27,[1]숨김!$B$3:$E$300,3,0) -> 4 | F27: =SUM(G27:L27) -> 4 | G27: 4 | M27: =SUM(G27:L30) -> 10 | O27: =VLOOKUP(D27,[1]숨김!$B$3:$E$300,4,0) -> 성취도 5단계+석차등급O
C28: =VLOOKUP(D28,[1]숨김!$B$3:$E$300,2,0) -> 공통 | D28: 통합과학2 | E28: =VLOOKUP(D28,[1]숨김!$B$3:$E$300,3,0) -> 4 | F28: =SUM(G28:L28) -> 4 | H28: 4 | O28: =VLOOKUP(D28,[1]숨김!$B$3:$E$300,4,0) -> 성취도 5단계+석차등급O
C29: =VLOOKUP(D29,[1]숨김!$B$3:$E$300,2,0) -> 공통 | D29: 과학탐구실험1 | E29: =VLOOKUP(D29,[1]숨김!$B$3:$E$300,3,0) -> 1 | F29: =SUM(G29:L29) -> 1 | G29: 1 | O29: =VLOOKUP(D29,[1]숨김!$B$3:$E$300,4,0) -> 성취도 3단계
C30: =VLOOKUP(D30,[1]숨김!$B$3:$E$300,2,0) -> 공통 | D30: 과학탐구실험2 | E30: =VLOOKUP(D30,[1]숨김!$B$3:$E$300,3,0) -> 1 | F30: =SUM(G30:L30) -> 1 | H30: 1 | O30: =VLOOKUP(D30,[1]숨김!$B$3:$E$300,4,0) -> 성취도 3단계
B31: 체육 | C31: =VLOOKUP(D31,[1]숨김!$B$3:$E$300,2,0) -> 일반 | D31: 체육1 | E31: =VLOOKUP(D31,[1]숨김!$B$3:$E$300,3,0) -> 3 | F31: =SUM(G31:L31) -> 2 | G31: 2 | M31: =SUM(G31:L36) -> 10 | O31: =VLOOKUP(D31,[1]숨김!$B$3:$E$300,4,0) -> 성취도 3단계
C32: =VLOOKUP(D32,[1]숨김!$B$3:$E$300,2,0) -> 일반 | D32: 체육2 | E32: =VLOOKUP(D32,[1]숨김!$B$3:$E$300,3,0) -> 3 | F32: =SUM(G32:L32) -> 2 | H32: 2 | O32: =VLOOKUP(D32,[1]숨김!$B$3:$E$300,4,0) -> 성취도 3단계
C33: =VLOOKUP(D33,[1]숨김!$B$3:$E$300,2,0) -> 융합 | D33: 스포츠 생활1 | E33: =VLOOKUP(D33,[1]숨김!$B$3:$E$300,3,0) -> 3 | F33: =SUM(G33:L33) -> 2 | I33: 2 | O33: =VLOOKUP(D33,[1]숨김!$B$3:$E$300,4,0) -> 성취도 3단계
C34: =VLOOKUP(D34,[1]숨김!$B$3:$E$300,2,0) -> 융합 | D34: 스포츠 생활2 | E34: =VLOOKUP(D34,[1]숨김!$B$3:$E$300,3,0) -> 3 | F34: =SUM(G34:L34) -> 2 | J34: 2 | O34: =VLOOKUP(D34,[1]숨김!$B$3:$E$300,4,0) -> 성취도 3단계
C35: =VLOOKUP(D35,[1]숨김!$B$3:$E$300,2,0) -> 진로 | D35: 스포츠 문화 | E35: =VLOOKUP(D35,[1]숨김!$B$3:$E$300,3,0) -> 2 | F35: =SUM(G35:L35) -> 1 | K35: 1 | O35: =VLOOKUP(D35,[1]숨김!$B$3:$E$300,4,0) -> 성취도 3단계
C36: =VLOOKUP(D36,[1]숨김!$B$3:$E$300,2,0) -> 진로 | D36: 스포츠 과학 | E36: =VLOOKUP(D36,[1]숨김!$B$3:$E$300,3,0) -> 2 | F36: =SUM(G36:L36) -> 1 | L36: 1 | O36: =VLOOKUP(D36,[1]숨김!$B$3:$E$300,4,0) -> 성취도 3단계
B37: 예술 | C37: 일반 | D37: 음악↔미술 | E37: 3 | F37: 3 | G37: 3 | H37: 3 | M37: =SUM(G37:L38) -> 6 | O37: 성취도 3단계
C38: 일반 | E38: 3 | F38: 3 | O38: 성취도 3단계
B39: 정보 | C39: =VLOOKUP(D39,[1]숨김!$B$3:$E$300,2,0) -> 일반 | D39: 정보 | E39: =VLOOKUP(D39,[1]숨김!$B$3:$E$300,3,0) -> 4 | F39: =SUM(G39:L39) -> 3 | G39: 3 | M39: =SUM(G39:L40) -> 6 | O39: =VLOOKUP(D39,[1]숨김!$B$3:$E$300,4,0) -> 성취도 5단계+석차등급O
C40: =VLOOKUP(D40,[1]숨김!$B$3:$E$300,2,0) -> 진로 | D40: 인공지능 기초 | E40: =VLOOKUP(D40,[1]숨김!$B$3:$E$300,3,0) -> 4 | F40: =SUM(G40:L40) -> 3 | H40: 3 | O40: =VLOOKUP(D40,[1]숨김!$B$3:$E$300,4,0) -> 성취도 5단계+석차등급O
...

Sheet 2026 입학생 3개년(2학년)
A1: 2026학년도 입학생 3개년 교육과정 편성표(2학년)
A2: 창원여자고등학교(공립)
A3: 구분 | B3: 교과(군) | C3: 과목 유형 | D3: 과목 | E3: 기본 학점 | F3: 운영 학점 | G3: 1학년 | I3: 2학년 | K3: 3학년 | M3: 편성학점 합 | O3: 성적처리 유형
G4: 1학기 | H4: 2학기 | I4: 1학기 | J4: 2학기 | K4: 1학기 | L4: 2학기 | M4: 교과(군) | N4: 선택군
A5: 학 교 지 정 과 목 | B5: 국어 | C5: 공통 | D5: 공통국어1 | E5: 4 | F5: =SUM(G5:L5) -> 3 | G5: 3 | M5: =SUM(G5:L10) -> 22 | N5: =SUM(M5:M22) -> 66 | O5: 성취도 5단계+석차등급O
C6: 공통 | D6: 공통국어2 | E6: 4 | F6: =SUM(G6:L6) -> 3 | H6: 3 | O6: 성취도 5단계+석차등급O
C7: 일반 | D7: 화법과 언어 | E7: 4 | F7: =SUM(G7:L7) -> 4 | I7: 4 | O7: 성취도 5단계+석차등급O
C8: 일반 | D8: 문학 | E8: 4 | F8: =SUM(G8:L8) -> 4 | J8: 4 | O8: 성취도 5단계+석차등급O
C9: 일반 | D9: 독서와 작문 | E9: 4 | F9: =SUM(G9:L9) -> 4 | K9: 4 | O9: 성취도 5단계+석차등급O
C10: 진로 | D10: 주제 탐구 독서 | E10: 4 | F10: =SUM(G10:L10) -> 4 | L10: 4 | O10: 성취도 5단계+석차등급O
B11: 수학 | C11: 공통 | D11: 공통수학1 | E11: 4 | F11: =SUM(G11:L11) -> 3 | G11: 3 | M11: =SUM(G11:L16) -> 22 | O11: 성취도 5단계+석차등급O
C12: 공통 | D12: 공통수학2 | E12: 4 | F12: =SUM(G12:L12) -> 3 | H12: 3 | O12: 성취도 5단계+석차등급O
C13: 일반 | D13: 대수 | E13: 4 | F13: =SUM(G13:L13) -> 4 | I13: 4 | O13: 성취도 5단계+석차등급O
C14: 일반 | D14: 미적분Ⅰ | E14: 4 | F14: =SUM(G14:L14) -> 4 | J14: 4 | O14: 성취도 5단계+석차등급O
C15: 일반 | D15: 확률과 통계 | E15: 4 | F15: =SUM(G15:L15) -> 4 | K15: 4 | O15: 성취도 5단계+석차등급O
C16: 융합 | D16: 수학과 문화 | E16: 4 | F16: =SUM(G16:L16) -> 4 | L16: 4 | O16: 성취도 5단계+석차등급O
B17: 영어 | C17: 공통 | D17: 공통영어1 | E17: 4 | F17: =SUM(G17:L17) -> 3 | G17: 3 | M17: =SUM(G17:L22) -> 22 | O17: 성취도 5단계+석차등급O
C18: 공통 | D18: 공통영어2 | E18: 4 | F18: =SUM(G18:L18) -> 3 | H18: 3 | O18: 성취도 5단계+석차등급O
C19: 일반 | D19: 영어Ⅰ | E19: 4 | F19: =SUM(G19:L19) -> 4 | I19: 4 | O19: 성취도 5단계+석차등급O
C20: 일반 | D20: 영어Ⅱ | E20: 4 | F20: =SUM(G20:L20) -> 4 | J20: 4 | O20: 성취도 5단계+석차등급O
C21: 일반 | D21: 영어 독해와 작문 | E21: 4 | F21: =SUM(G21:L21) -> 4 | K21: 4 | O21: 성취도 5단계+석차등급O
C22: 진로 | D22: 심화 영어 독해와 작문 | E22: 4 | F22: =SUM(G22:L22) -> 4 | L22: 4 | O22: 성취도 5단계+석차등급O
B23: 사회 | C23: 공통 | D23: 한국사1 | E23: 3 | F23: =SUM(G23:L23) -> 3 | G23: 3 | M23: =SUM(G23:L24) -> 6 | O23: 성취도 5단계+석차등급O
C24: 공통 | D24: 한국사2 | E24: 3 | F24: =SUM(G24:L24) -> 3 | H24: 3 | O24: 성취도 5단계+석차등급O
C25: 공통 | D25: 통합사회1 | E25: 4 | F25: =SUM(G25:L25) -> 4 | G25: 4 | M25: =SUM(G25:L28) -> 16 | O25: 성취도 5단계+석차등급O
C26: 공통 | D26: 통합사회2 | E26: 4 | F26: =SUM(G26:L26) -> 4 | H26: 4 | O26: 성취도 5단계+석차등급O
B27: 과학 | C27: 공통 | D27: 통합과학1 | E27: 4 | F27: =SUM(G27:L27) -> 4 | G27: 4 | M27: =SUM(G29:L37) -> 18 | O27: 성취도 5단계+석차등급O
C28: 공통 | D28: 통합과학2 | E28: 4 | F28: =SUM(G28:L28) -> 4 | H28: 4 | O28: 성취도 5단계+석차등급O
C29: 공통 | D29: 과학탐구실험1 | E29: 1 | F29: =SUM(G29:L29) -> 1 | G29: 1 | O29: 성취도 3단계
C30: 공통 | D30: 과학탐구실험2 | E30: 1 | F30: =SUM(G30:L30) -> 1 | H30: 1 | O30: 성취도 3단계
B31: 체육 | C31: 일반 | D31: 체육1 | E31: 3 | F31: =SUM(G31:L31) -> 2 | G31: 2 | M31: =SUM(G31:L36) -> 10 | O31: 성취도 3단계
C32: 일반 | D32: 체육2 | E32: 3 | F32: =SUM(G32:L32) -> 2 | H32: 2 | O32: 성취도 3단계
C33: 융합 | D33: 스포츠 생활1 | E33: 3 | F33: =SUM(G33:L33) -> 2 | I33: 2 | O33: 성취도 3단계
C34: 융합 | D34: 스포츠 생활2 | E34: 3 | F34: =SUM(G34:L34) -> 2 | J34: 2 | O34: 성취도 3단계
C35: 진로 | D35: 스포츠 문화 | E35: 2 | F35: =SUM(G35:L35) -> 1 | K35: 1 | O35: 성취도 3단계
C36: 진로 | D36: 스포츠 과학 | E36: 2 | F36: =SUM(G36:L36) -> 1 | L36: 1 | O36: 성취도 3단계
B37: 예술 | C37: 일반 | D37: 음악↔미술 | E37: 3 | F37: 3 | G37: 3 | H37: 3 | M37: =SUM(G37:L40) -> 10 | O37: 성취도 3단계
C38: 일반 | E38: 3 | F38: 3 | O38: 성취도 3단계
C39: 진로 | D39: 음악 연주와 창작↔미술 창작 | E39: 3 | F39: 2 | K39: 2 | L39: 2 | O39: 성취도 3단계
C40: 진로 | E40: 3 | F40: 2 | O40: 성취도 3단계
...

Sheet 2025 입학생 3개년(3학년)
A1: 2025학년도 입학생 3개년 교육과정 편성표(3학년)
A2: 창원여자고등학교(공립)
A3: 구분 | B3: 교과(군) | C3: 과목 유형 | D3: 과목 | E3: 기본 학점 | F3: 운영 학점 | G3: 1학년 | I3: 2학년 | K3: 3학년 | M3: 편성학점 합 | O3: 성적처리 유형
G4: 1학기 | H4: 2학기 | I4: 1학기 | J4: 2학기 | K4: 1학기 | L4: 2학기 | M4: 교과(군) | N4: 선택군
A5: 학 교 지 정 과 목 | B5: 국어 | C5: 공통 | D5: 공통국어1 | E5: 4 | F5: =SUM(G5:L5) -> 3 | G5: 3 | M5: =SUM(G5:L10) -> 22 | N5: =SUM(M5:M22) -> 66 | O5: 성취도 5단계+석차등급O
C6: 공통 | D6: 공통국어2 | E6: 4 | F6: =SUM(G6:L6) -> 3 | H6: 3 | O6: 성취도 5단계+석차등급O
C7: 일반 | D7: 화법과 언어 | E7: 4 | F7: =SUM(G7:L7) -> 4 | I7: 4 | O7: 성취도 5단계+석차등급O
C8: 일반 | D8: 문학 | E8: 4 | F8: =SUM(G8:L8) -> 4 | J8: 4 | O8: 성취도 5단계+석차등급O
C9: 일반 | D9: 독서와 작문 | E9: 4 | F9: =SUM(G9:L9) -> 4 | K9: 4 | O9: 성취도 5단계+석차등급O
C10: 진로 | D10: 주제 탐구 독서 | E10: 4 | F10: =SUM(G10:L10) -> 4 | L10: 4 | O10: 성취도 5단계+석차등급O
B11: 수학 | C11: 공통 | D11: 공통수학1 | E11: 4 | F11: =SUM(G11:L11) -> 3 | G11: 3 | M11: =SUM(G11:L16) -> 22 | O11: 성취도 5단계+석차등급O
C12: 공통 | D12: 공통수학2 | E12: 4 | F12: =SUM(G12:L12) -> 3 | H12: 3 | O12: 성취도 5단계+석차등급O
C13: 일반 | D13: 대수 | E13: 4 | F13: =SUM(G13:L13) -> 4 | I13: 4 | O13: 성취도 5단계+석차등급O
C14: 일반 | D14: 미적분Ⅰ | E14: 4 | F14: =SUM(G14:L14) -> 4 | J14: 4 | O14: 성취도 5단계+석차등급O
C15: 일반 | D15: 확률과 통계 | E15: 4 | F15: =SUM(G15:L15) -> 4 | K15: 4 | O15: 성취도 5단계+석차등급O
C16: 융합 | D16: 수학과 문화 | E16: 4 | F16: =SUM(G16:L16) -> 4 | L16: 4 | O16: 성취도 5단계+석차등급O
B17: 영어 | C17: 공통 | D17: 공통영어1 | E17: 4 | F17: =SUM(G17:L17) -> 3 | G17: 3 | M17: =SUM(G17:L22) -> 22 | O17: 성취도 5단계+석차등급O
C18: 공통 | D18: 공통영어2 | E18: 4 | F18: =SUM(G18:L18) -> 3 | H18: 3 | O18: 성취도 5단계+석차등급O
C19: 일반 | D19: 영어Ⅰ | E19: 4 | F19: =SUM(G19:L19) -> 4 | I19: 4 | O19: 성취도 5단계+석차등급O
C20: 일반 | D20: 영어Ⅱ | E20: 4 | F20: =SUM(G20:L20) -> 4 | J20: 4 | O20: 성취도 5단계+석차등급O
C21: 일반 | D21: 영어 독해와 작문 | E21: 4 | F21: =SUM(G21:L21) -> 4 | K21: 4 | O21: 성취도 5단계+석차등급O
C22: 진로 | D22: 심화 영어 독해와 작문 | E22: 4 | F22: =SUM(G22:L22) -> 4 | L22: 4 | O22: 성취도 5단계+석차등급O
B23: 사회 | C23: 공통 | D23: 한국사1 | E23: 3 | F23: =SUM(G23:L23) -> 3 | G23: 3 | M23: =SUM(G23:L24) -> 6 | O23: 성취도 5단계+석차등급O
C24: 공통 | D24: 한국사2 | E24: 3 | F24: =SUM(G24:L24) -> 3 | H24: 3 | O24: 성취도 5단계+석차등급O
C25: 공통 | D25: 통합사회1 | E25: 4 | F25: =SUM(G25:L25) -> 4 | G25: 4 | M25: =SUM(G25:L28) -> 16 | O25: 성취도 5단계+석차등급O
C26: 공통 | D26: 통합사회2 | E26: 4 | F26: =SUM(G26:L26) -> 4 | H26: 4 | O26: 성취도 5단계+석차등급O
B27: 과학 | C27: 공통 | D27: 통합과학1 | E27: 4 | F27: =SUM(G27:L27) -> 4 | G27: 4 | M27: =SUM(G29:L37) -> 18 | O27: 성취도 5단계+석차등급O
C28: 공통 | D28: 통합과학2 | E28: 4 | F28: =SUM(G28:L28) -> 4 | H28: 4 | O28: 성취도 5단계+석차등급O
C29: 공통 | D29: 과학탐구실험1 | E29: 1 | F29: =SUM(G29:L29) -> 1 | G29: 1 | O29: 성취도 3단계
C30: 공통 | D30: 과학탐구실험2 | E30: 1 | F30: =SUM(G30:L30) -> 1 | H30: 1 | O30: 성취도 3단계
B31: 체육 | C31: 일반 | D31: 체육1 | E31: 3 | F31: =SUM(G31:L31) -> 2 | G31: 2 | M31: =SUM(G31:L36) -> 10 | O31: 성취도 3단계
C32: 일반 | D32: 체육2 | E32: 3 | F32: =SUM(G32:L32) -> 2 | H32: 2 | O32: 성취도 3단계
C33: 융합 | D33: 스포츠 생활1 | E33: 3 | F33: =SUM(G33:L33) -> 2 | I33: 2 | O33: 성취도 3단계
C34: 융합 | D34: 스포츠 생활2 | E34: 3 | F34: =SUM(G34:L34) -> 2 | J34: 2 | O34: 성취도 3단계
C35: 진로 | D35: 스포츠 문화 | E35: 2 | F35: =SUM(G35:L35) -> 1 | K35: 1 | O35: 성취도 3단계
C36: 진로 | D36: 스포츠 과학 | E36: 2 | F36: =SUM(G36:L36) -> 1 | L36: 1 | O36: 성취도 3단계
B37: 예술 | C37: 일반 | D37: 음악↔미술 | E37: 3 | F37: 3 | G37: 3 | H37: 3 | M37: =SUM(G37:L40) -> 10 | O37: 성취도 3단계
C38: 일반 | E38: 3 | F38: 3 | O38: 성취도 3단계
C39: 진로 | D39: 음악 연주와 창작↔미술 창작 | E39: 3 | F39: 2 | K39: 2 | L39: 2 | O39: 성취도 3단계
C40: 진로 | E40: 3 | F40: 2 | O40: 성취도 3단계
...

Sheet (2022)보통교과 목록
B1: 2022 개정 교육과정 고등학교 보통교과 교과목 목록
F3: =SUBTOTAL(3,F5:F298) -> 290
B4: 연번 | C4: 계열 | D4: 교과(군) | E4: 구분 | F4: 과목명 | G4: 기본 학점 | H4: 학점 범위 | I4: 성적 처리 유형 | J4: 2028 수능 과목 여부 | K4: 비고
B5: 1 | D5: 국어 | E5: 공통 과목 | F5: 공통국어1 | G5: 4학점 | H5: 3~4 | I5: 성취도 5단계+석차 5등급
B6: 2 | D6: 국어 | E6: 공통 과목 | F6: 공통국어2 | G6: 4학점 | H6: 3~4 | I6: 성취도 5단계+석차 5등급
B7: 3 | D7: 국어 | E7: 일반 선택 과목 | F7: 화법과 언어 | G7: 4학점 | H7: 3~5 | I7: 성취도 5단계+석차 5등급 | J7: 국어영역 출제과목
B8: 4 | D8: 국어 | E8: 일반 선택 과목 | F8: 독서와 작문 | G8: 4학점 | H8: 3~5 | I8: 성취도 5단계+석차 5등급 | J8: 국어영역 출제과목
B9: 5 | D9: 국어 | E9: 일반 선택 과목 | F9: 문학 | G9: 4학점 | H9: 3~5 | I9: 성취도 5단계+석차 5등급 | J9: 국어영역 출제과목
B10: 6 | D10: 국어 | E10: 진로 선택 과목 | F10: 주제 탐구 독서 | G10: 4학점 | H10: 3~5 | I10: 성취도 5단계+석차 5등급
B11: 7 | D11: 국어 | E11: 진로 선택 과목 | F11: 문학과 영상 | G11: 4학점 | H11: 3~5 | I11: 성취도 5단계+석차 5등급
B12: 8 | D12: 국어 | E12: 진로 선택 과목 | F12: 직무 의사소통 | G12: 4학점 | H12: 3~5 | I12: 성취도 5단계+석차 5등급
B13: 9 | D13: 국어 | E13: 융합 선택 과목 | F13: 독서 토론과 글쓰기 | G13: 4학점 | H13: 3~5 | I13: 성취도 5단계+석차 5등급
B14: 10 | D14: 국어 | E14: 융합 선택 과목 | F14: 매체 의사소통 | G14: 4학점 | H14: 3~5 | I14: 성취도 5단계+석차 5등급
B15: 11 | D15: 국어 | E15: 융합 선택 과목 | F15: 언어생활 탐구 | G15: 4학점 | H15: 3~5 | I15: 성취도 5단계+석차 5등급
B16: 12 | D16: 수학 | E16: 공통 과목 | F16: 공통수학1 | G16: 4학점 | H16: 3~4 | I16: 성취도 5단계+석차 5등급
B17: 13 | D17: 수학 | E17: 공통 과목 | F17: 공통수학2 | G17: 4학점 | H17: 3~4 | I17: 성취도 5단계+석차 5등급
B18: 14 | D18: 수학 | E18: 공통 과목 | F18: 기본수학1 | G18: 4학점 | H18: 3~4 | I18: 성취도 5단계+석차 5등급
B19: 15 | D19: 수학 | E19: 공통 과목 | F19: 기본수학2 | G19: 4학점 | H19: 3~4 | I19: 성취도 5단계+석차 5등급
B20: 16 | D20: 수학 | E20: 일반 선택 과목 | F20: 대수 | G20: 4학점 | H20: 3~5 | I20: 성취도 5단계+석차 5등급 | J20: 수학영역 출제과목
B21: 17 | D21: 수학 | E21: 일반 선택 과목 | F21: 미적분Ⅰ | G21: 4학점 | H21: 3~5 | I21: 성취도 5단계+석차 5등급 | J21: 수학영역 출제과목 | K21: 과목 위계에 주의
B22: 18 | D22: 수학 | E22: 일반 선택 과목 | F22: 확률과 통계 | G22: 4학점 | H22: 3~5 | I22: 성취도 5단계+석차 5등급 | J22: 수학영역 출제과목
B23: 19 | D23: 수학 | E23: 진로 선택 과목 | F23: 기하 | G23: 4학점 | H23: 3~5 | I23: 성취도 5단계+석차 5등급
B24: 20 | D24: 수학 | E24: 진로 선택 과목 | F24: 미적분Ⅱ | G24: 4학점 | H24: 3~5 | I24: 성취도 5단계+석차 5등급 | K24: 과목 위계에 주의
B25: 21 | D25: 수학 | E25: 진로 선택 과목 | F25: 경제 수학 | G25: 4학점 | H25: 3~5 | I25: 성취도 5단계+석차 5등급
B26: 22 | D26: 수학 | E26: 진로 선택 과목 | F26: 인공지능 수학 | G26: 4학점 | H26: 3~5 | I26: 성취도 5단계+석차 5등급
B27: 23 | D27: 수학 | E27: 진로 선택 과목 | F27: 직무 수학 | G27: 4학점 | H27: 3~5 | I27: 성취도 5단계+석차 5등급
B28: 24 | D28: 수학 | E28: 융합 선택 과목 | F28: 수학과 문화 | G28: 4학점 | H28: 3~5 | I28: 성취도 5단계+석차 5등급
B29: 25 | D29: 수학 | E29: 융합 선택 과목 | F29: 실용 통계 | G29: 4학점 | H29: 3~5 | I29: 성취도 5단계+석차 5등급
B30: 26 | D30: 수학 | E30: 융합 선택 과목 | F30: 수학과제 탐구 | G30: 4학점 | H30: 3~5 | I30: 성취도 5단계+석차 5등급
B31: 27 | D31: 영어 | E31: 공통 과목 | F31: 공통영어1 | G31: 4학점 | H31: 3~4 | I31: 성취도 5단계+석차 5등급
B32: 28 | D32: 영어 | E32: 공통 과목 | F32: 공통영어2 | G32: 4학점 | H32: 3~4 | I32: 성취도 5단계+석차 5등급
B33: 29 | D33: 영어 | E33: 공통 과목 | F33: 기본영어1 | G33: 4학점 | H33: 3~4 | I33: 성취도 5단계+석차 5등급
B34: 30 | D34: 영어 | E34: 공통 과목 | F34: 기본영어2 | G34: 4학점 | H34: 3~4 | I34: 성취도 5단계+석차 5등급
B35: 31 | D35: 영어 | E35: 일반 선택 과목 | F35: 영어Ⅰ | G35: 4학점 | H35: 3~5 | I35: 성취도 5단계+석차 5등급 | J35: 영어영역 출제과목 | K35: 과목 위계에 주의
B36: 32 | D36: 영어 | E36: 일반 선택 과목 | F36: 영어Ⅱ | G36: 4학점 | H36: 3~5 | I36: 성취도 5단계+석차 5등급 | J36: 영어영역 출제과목 | K36: 과목 위계에 주의
B37: 33 | D37: 영어 | E37: 일반 선택 과목 | F37: 영어 독해와 작문 | G37: 4학점 | H37: 3~5 | I37: 성취도 5단계+석차 5등급
B38: 34 | D38: 영어 | E38: 진로 선택 과목 | F38: 영미 문학 읽기 | G38: 4학점 | H38: 3~5 | I38: 성취도 5단계+석차 5등급
B39: 35 | D39: 영어 | E39: 진로 선택 과목 | F39: 영어 발표와 토론 | G39: 4학점 | H39: 3~5 | I39: 성취도 5단계+석차 5등급
B40: 36 | D40: 영어 | E40: 진로 선택 과목 | F40: 심화 영어 | G40: 4학점 | H40: 3~5 | I40: 성취도 5단계+석차 5등급
B41: 37 | D41: 영어 | E41: 진로 선택 과목 | F41: 심화 영어 독해와 작문 | G41: 4학점 | H41: 3~5 | I41: 성취도 5단계+석차 5등급
...

Sheet 숨김
B1: =SUBTOTAL(3,B3:B298) -> 290
A2: 교과군 | B2: 과목명 | C2: 유형 | D2: 기본학점 | E2: 성적 처리 유형 | F2: 편성 최소 학점 | G2: 편성 최대 학점 | H2: 편성 학점 범위 | I2: 비고
A3: 국어 | B3: 공통국어1 | C3: 공통 | D3: 4 | E3: 성취도 5단계+석차등급O | F3: 3 | G3: 4 | H3: 3~4
A4: 국어 | B4: 공통국어2 | C4: 공통 | D4: 4 | E4: 성취도 5단계+석차등급O | F4: 3 | G4: 4 | H4: 3~4
A5: 국어 | B5: 화법과 언어 | C5: 일반 | D5: 4 | E5: 성취도 5단계+석차등급O | F5: 3 | G5: 5 | H5: 3~5
A6: 국어 | B6: 독서와 작문 | C6: 일반 | D6: 4 | E6: 성취도 5단계+석차등급O | F6: 3 | G6: 5 | H6: 3~5
A7: 국어 | B7: 문학 | C7: 일반 | D7: 4 | E7: 성취도 5단계+석차등급O | F7: 3 | G7: 5 | H7: 3~5
A8: 국어 | B8: 주제 탐구 독서 | C8: 진로 | D8: 4 | E8: 성취도 5단계+석차등급O | F8: 3 | G8: 5 | H8: 3~5
A9: 국어 | B9: 문학과 영상 | C9: 진로 | D9: 4 | E9: 성취도 5단계+석차등급O | F9: 3 | G9: 5 | H9: 3~5
A10: 국어 | B10: 직무 의사소통 | C10: 진로 | D10: 4 | E10: 성취도 5단계+석차등급O | F10: 3 | G10: 5 | H10: 3~5
A11: 국어 | B11: 독서 토론과 글쓰기 | C11: 융합 | D11: 4 | E11: 성취도 5단계+석차등급O | F11: 3 | G11: 5 | H11: 3~5
A12: 국어 | B12: 매체 의사소통 | C12: 융합 | D12: 4 | E12: 성취도 5단계+석차등급O | F12: 3 | G12: 5 | H12: 3~5
A13: 국어 | B13: 언어생활 탐구 | C13: 융합 | D13: 4 | E13: 성취도 5단계+석차등급O | F13: 3 | G13: 5 | H13: 3~5
A14: 수학 | B14: 공통수학1 | C14: 공통 | D14: 4 | E14: 성취도 5단계+석차등급O | F14: 3 | G14: 4 | H14: 3~4
... A43: 영어 | B43: 세계 문화와 영어 | C43: 융합 | D43: 4 | E43: 성취도 5단계+석차등급O | F43: 3 | G43: 5 | H43: 3~5
A44: 사회 | B44: 한국사1 | C44: 공통 | D44: 3 | E44: 성취도 5단계+석차등급O | F44: 3 | G44: 3 | H44: 3
A45: 사회 | B45: 한국사2 | C45: 공통 | D45: 3 | E45: 성취도 5단계+석차등급O | F45: 3 | G45: 3 | H45: 3
A46: 사회 | B46: 통합사회1 | C46: 공통 | D46: 4 | E46: 성취도 5단계+석차등급O | F46: 3 | G46: 4 | H46: 3~4
A47: 사회 | B47: 통합사회2 | C47: 공통 | D47: 4 | E47: 성취도 5단계+석차등급O | F47: 3 | G47: 4 | H47: 3~4
A48: 사회 | B48: 세계시민과 지리 | C48: 일반 | D48: 4 | E48: 성취도 5단계+석차등급O | F48: 3 | G48: 5 | H48: 3~5
A49: 사회 | B49: 세계사 | C49: 일반 | D49: 4 | E49: 성취도 5단계+석차등급O | F49: 3 | G49: 5 | H49: 3~5
A50: 사회 | B50: 사회와 문화 | C50: 일반 | D50: 4 | E50: 성취도 5단계+석차등급O | F50: 3 | G50: 5 | H50: 3~5
A51: 사회 | B51: 현대사회와 윤리 | C51: 일반 | D51: 4 | E51: 성취도 5단계+석차등급O | F51: 3 | G51: 5 | H51: 3~5
A52: 사회 | B52: 한국지리 탐구 | C52: 진로 | D52: 4 | E52: 성취도 5단계+석차등급O | F52: 3 | G52: 5 | H52: 3~5
A53: 사회 | B53: 도시의 미래 탐구 | C53: 진로 | D53: 4 | E53: 성취도 5단계+석차등급O | F53: 3 | G53: 5 | H53: 3~5
A54: 사회 | B54: 동아시아 역사 기행 | C54: 진로 | D54: 4 | E54: 성취도 5단계+석차등급O | F54: 3 | G54: 5 | H54: 3~5
A55: 사회 | B55: 정치 | C55: 진로 | D55: 4 | E55: 성취도 5단계+석차등급O | F55: 3 | G55: 5 | H55: 3~5
A56: 사회 | B56: 법과 사회 | C56: 진로 | D56: 4 | E56: 성취도 5단계+석차등급O | F56: 3 | G56: 5 | H56: 3~5
A57: 사회 | B57: 경제 | C57: 진로 | D57: 4 | E57: 성취도 5단계+석차등급O | F57: 3 | G57: 5 | H57: 3~5
... A68: 과학 | B68: 통합과학2 | C68: 공통 | D68: 4 | E68: 성취도 5단계+석차등급O | F68: 3 | G68: 4 | H68: 3~4
A69: 과학 | B69: 과학탐구실험1 | C69: 공통 | D69: 1 | E69: 성취도 3단계 | F69: 1 | G69: 1 | H69: 1
A70: 과학 | B70: 과학탐구실험2 | C70: 공통 | D70: 1 | E70: 성취도 3단계 | F70: 1 | G70: 1 | H70: 1
A71: 과학 | B71: 물리학 | C71: 일반 | D71: 4 | E71: 성취도 5단계+석차등급O | F71: 3 | G71: 5 | H71: 3~5
A72: 과학 | B72: 화학 | C72: 일반 | D72: 4 | E72: 성취도 5단계+석차등급O | F72: 3 | G72: 5 | H72: 3~5
A73: 과학 | B73: 생명과학 | C73: 일반 | D73: 4 | E73: 성취도 5단계+석차등급O | F73: 3 | G73: 5 | H73: 3~5
A74: 과학 | B74: 지구과학 | C74: 일반 | D74: 4 | E74: 성취도 5단계+석차등급O | F74: 3 | G74: 5 | H74: 3~5
A75: 과학 | B75: 역학과 에너지 | C75: 진로 | D75: 4 | E75: 성취도 5단계+석차등급O | F75: 3 | G75: 5 | H75: 3~5
A76: 과학 | B76: 전자기와 양자 | C76: 진로 | D76: 4 | E76: 성취도 5단계+석차등급O | F76: 3 | G76: 5 | H76: 3~5
A77: 과학 | B77: 물질과 에너지 | C77: 진로 | D77: 4 | E77: 성취도 5단계+석차등급O | F77: 3 | G77: 5 | H77: 3~5
A78: 과학 | B78: 화학 반응의 세계 | C78: 진로 | D78: 4 | E78: 성취도 5단계+석차등급O | F78: 3 | G78: 5 | H78: 3~5
...
